<?xml version="1.0" encoding="UTF-8"?>
<testng-results ignored="0" total="4" passed="1" failed="1" skipped="2">
  <reporter-output>
  </reporter-output>
  <suite started-at="2023-07-13T13:19:54 IST" name="Default suite" finished-at="2023-07-13T13:19:54 IST" duration-ms="283">
    <groups>
    </groups>
    <test started-at="2023-07-13T13:19:54 IST" name="Default test" finished-at="2023-07-13T13:19:54 IST" duration-ms="283">
      <class name="TestNGOne.assertFail">
        <test-method signature="software()[pri:0, instance:TestNGOne.assertFail@45099dd3]" started-at="2023-07-13T13:19:54 IST" name="software" finished-at="2023-07-13T13:19:54 IST" duration-ms="45" status="FAIL">
          <exception class="java.lang.AssertionError">
            <message>
              <![CDATA[null]]>
            </message>
            <full-stacktrace>
              <![CDATA[java.lang.AssertionError: null
at org.testng.Assert.fail(Assert.java:111)
at org.testng.Assert.fail(Assert.java:116)
at TestNGOne.assertFail.software(assertFail.java:17)
at java.base/jdk.internal.reflect.NativeMethodAccessorImpl.invoke0(Native Method)
at java.base/jdk.internal.reflect.NativeMethodAccessorImpl.invoke(NativeMethodAccessorImpl.java:77)
at java.base/jdk.internal.reflect.DelegatingMethodAccessorImpl.invoke(DelegatingMethodAccessorImpl.java:43)
at java.base/java.lang.reflect.Method.invoke(Method.java:568)
at org.testng.internal.invokers.MethodInvocationHelper.invokeMethod(MethodInvocationHelper.java:139)
at org.testng.internal.invokers.TestInvoker.invokeMethod(TestInvoker.java:664)
at org.testng.internal.invokers.TestInvoker.invokeTestMethod(TestInvoker.java:227)
at org.testng.internal.invokers.MethodRunner.runInSequence(MethodRunner.java:50)
at org.testng.internal.invokers.TestInvoker$MethodInvocationAgent.invoke(TestInvoker.java:957)
at org.testng.internal.invokers.TestInvoker.invokeTestMethods(TestInvoker.java:200)
at org.testng.internal.invokers.TestMethodWorker.invokeTestMethods(TestMethodWorker.java:148)
at org.testng.internal.invokers.TestMethodWorker.run(TestMethodWorker.java:128)
at java.base/java.util.ArrayList.forEach(ArrayList.java:1511)
at org.testng.TestRunner.privateRun(TestRunner.java:848)
at org.testng.TestRunner.run(TestRunner.java:621)
at org.testng.SuiteRunner.runTest(SuiteRunner.java:443)
at org.testng.SuiteRunner.runSequentially(SuiteRunner.java:437)
at org.testng.SuiteRunner.privateRun(SuiteRunner.java:397)
at org.testng.SuiteRunner.run(SuiteRunner.java:336)
at org.testng.SuiteRunnerWorker.runSuite(SuiteRunnerWorker.java:52)
at org.testng.SuiteRunnerWorker.run(SuiteRunnerWorker.java:95)
at org.testng.TestNG.runSuitesSequentially(TestNG.java:1280)
at org.testng.TestNG.runSuitesLocally(TestNG.java:1200)
at org.testng.TestNG.runSuites(TestNG.java:1114)
at org.testng.TestNG.run(TestNG.java:1082)
at org.testng.remote.AbstractRemoteTestNG.run(AbstractRemoteTestNG.java:115)
at org.testng.remote.RemoteTestNG.initAndRun(RemoteTestNG.java:251)
at org.testng.remote.RemoteTestNG.main(RemoteTestNG.java:77)
]]>
            </full-stacktrace>
          </exception> <!-- java.lang.AssertionError -->
          <reporter-output>
          </reporter-output>
        </test-method> <!-- software -->
        <test-method signature="users()[pri:0, instance:TestNGOne.assertFail@45099dd3]" started-at="2023-07-13T13:19:54 IST" name="users" finished-at="2023-07-13T13:19:54 IST" duration-ms="9" status="PASS">
          <reporter-output>
          </reporter-output>
        </test-method> <!-- users -->
        <test-method signature="developer()[pri:0, instance:TestNGOne.assertFail@45099dd3]" started-at="2023-07-13T13:19:54 IST" name="developer" finished-at="2023-07-13T13:19:54 IST" depends-on-methods="TestNGOne.assertFail.software" duration-ms="1" status="SKIP">
          <exception class="java.lang.Throwable">
            <message>
              <![CDATA[Method TestNGOne.assertFail.developer() on instance TestNGOne.assertFail@45099dd3 depends on not successfully finished methods 
[TestNGOne.assertFail.software() on instance TestNGOne.assertFail@45099dd3]]]>
            </message>
            <full-stacktrace>
              <![CDATA[java.lang.Throwable: Method TestNGOne.assertFail.developer() on instance TestNGOne.assertFail@45099dd3 depends on not successfully finished methods 
[TestNGOne.assertFail.software() on instance TestNGOne.assertFail@45099dd3]
at org.testng.internal.invokers.TestInvoker.invokeTestMethods(TestInvoker.java:156)
at org.testng.internal.invokers.TestMethodWorker.invokeTestMethods(TestMethodWorker.java:148)
at org.testng.internal.invokers.TestMethodWorker.run(TestMethodWorker.java:128)
at java.base/java.util.ArrayList.forEach(ArrayList.java:1511)
at org.testng.TestRunner.privateRun(TestRunner.java:848)
at org.testng.TestRunner.run(TestRunner.java:621)
at org.testng.SuiteRunner.runTest(SuiteRunner.java:443)
at org.testng.SuiteRunner.runSequentially(SuiteRunner.java:437)
at org.testng.SuiteRunner.privateRun(SuiteRunner.java:397)
at org.testng.SuiteRunner.run(SuiteRunner.java:336)
at org.testng.SuiteRunnerWorker.runSuite(SuiteRunnerWorker.java:52)
at org.testng.SuiteRunnerWorker.run(SuiteRunnerWorker.java:95)
at org.testng.TestNG.runSuitesSequentially(TestNG.java:1280)
at org.testng.TestNG.runSuitesLocally(TestNG.java:1200)
at org.testng.TestNG.runSuites(TestNG.java:1114)
at org.testng.TestNG.run(TestNG.java:1082)
at org.testng.remote.AbstractRemoteTestNG.run(AbstractRemoteTestNG.java:115)
at org.testng.remote.RemoteTestNG.initAndRun(RemoteTestNG.java:251)
at org.testng.remote.RemoteTestNG.main(RemoteTestNG.java:77)
]]>
            </full-stacktrace>
          </exception> <!-- java.lang.Throwable -->
          <reporter-output>
          </reporter-output>
        </test-method> <!-- developer -->
        <test-method signature="tester()[pri:0, instance:TestNGOne.assertFail@45099dd3]" started-at="2023-07-13T13:19:54 IST" name="tester" finished-at="2023-07-13T13:19:54 IST" depends-on-methods="TestNGOne.assertFail.developer" duration-ms="0" status="SKIP">
          <exception class="java.lang.Throwable">
            <message>
              <![CDATA[Method TestNGOne.assertFail.tester() on instance TestNGOne.assertFail@45099dd3 depends on not successfully finished methods 
[TestNGOne.assertFail.developer() on instance TestNGOne.assertFail@45099dd3]]]>
            </message>
            <full-stacktrace>
              <![CDATA[java.lang.Throwable: Method TestNGOne.assertFail.tester() on instance TestNGOne.assertFail@45099dd3 depends on not successfully finished methods 
[TestNGOne.assertFail.developer() on instance TestNGOne.assertFail@45099dd3]
at org.testng.internal.invokers.TestInvoker.invokeTestMethods(TestInvoker.java:156)
at org.testng.internal.invokers.TestMethodWorker.invokeTestMethods(TestMethodWorker.java:148)
at org.testng.internal.invokers.TestMethodWorker.run(TestMethodWorker.java:128)
at java.base/java.util.ArrayList.forEach(ArrayList.java:1511)
at org.testng.TestRunner.privateRun(TestRunner.java:848)
at org.testng.TestRunner.run(TestRunner.java:621)
at org.testng.SuiteRunner.runTest(SuiteRunner.java:443)
at org.testng.SuiteRunner.runSequentially(SuiteRunner.java:437)
at org.testng.SuiteRunner.privateRun(SuiteRunner.java:397)
at org.testng.SuiteRunner.run(SuiteRunner.java:336)
at org.testng.SuiteRunnerWorker.runSuite(SuiteRunnerWorker.java:52)
at org.testng.SuiteRunnerWorker.run(SuiteRunnerWorker.java:95)
at org.testng.TestNG.runSuitesSequentially(TestNG.java:1280)
at org.testng.TestNG.runSuitesLocally(TestNG.java:1200)
at org.testng.TestNG.runSuites(TestNG.java:1114)
at org.testng.TestNG.run(TestNG.java:1082)
at org.testng.remote.AbstractRemoteTestNG.run(AbstractRemoteTestNG.java:115)
at org.testng.remote.RemoteTestNG.initAndRun(RemoteTestNG.java:251)
at org.testng.remote.RemoteTestNG.main(RemoteTestNG.java:77)
]]>
            </full-stacktrace>
          </exception> <!-- java.lang.Throwable -->
          <reporter-output>
          </reporter-output>
        </test-method> <!-- tester -->
      </class> <!-- TestNGOne.assertFail -->
    </test> <!-- Default test -->
  </suite> <!-- Default suite -->
</testng-results>
